<?xml version="1.0" encoding="utf-8"?>
<!-- This URDF was automatically created by SolidWorks to URDF Exporter! Originally created by Stephen Brawner (brawner@gmail.com) 
     Commit Version: 1.6.0-1-g15f4949  Build Version: 1.6.7594.29634
     For more information, please see http://wiki.ros.org/sw_urdf_exporter -->
<robot
  name="xingtian">

  <link 
     name="dummy">
  </link>
  <joint name="dummy_joint" type="fixed">
     <parent link="dummy"/>
     <child link="base_link"/>
  </joint>

  <link
    name="base_link">
    <inertial>
      <origin
        xyz="-6.22738938177436E-06 2.56447575640306E-07 0.000487551856888666"
        rpy="0 0 0" />
      <mass
        value="17.0402871840263" />
      <inertia
        ixx="0.118814323679022"
        ixy="3.25903296893552E-06"
        ixz="-1.50660653722835E-05"
        iyy="2.09521688070061"
        iyz="-8.32187434939351E-09"
        izz="2.06149777825353" />
    </inertial>
    <visual>
      <origin
        xyz="0 0 0"
        rpy="0 0 0" />
      <geometry>
        <mesh
          filename="package://xingtian/meshes/base_link.STL" />
      </geometry>
      <material
        name="">
        <color
          rgba="0.796078431372549 0.823529411764706 0.937254901960784 1" />
      </material>
    </visual>
    <collision>
      <origin
        xyz="0 0 0"
        rpy="0 0 0" />
      <geometry>
        <mesh
          filename="package://xingtian/meshes/base_link.STL" />
      </geometry>
    </collision>
  </link>
  <link
    name="imu_link">
    <inertial>
      <origin
        xyz="0 0 -0.005"
        rpy="0 0 0" />
      <mass
        value="0.00899999999999999" />
      <inertia
        ixx="7.49999999999999E-07"
        ixy="-1.26133558763496E-22"
        ixz="-3.89334058238209E-23"
        iyy="7.49999999999998E-07"
        iyz="1.61565069752578E-22"
        izz="1.35E-06" />
    </inertial>
    <visual>
      <origin
        xyz="0 0 0"
        rpy="0 0 0" />
      <geometry>
        <mesh
          filename="package://xingtian/meshes/imu_link.STL" />
      </geometry>
      <material
        name="">
        <color
          rgba="1 1 1 1" />
      </material>
    </visual>
    <collision>
      <origin
        xyz="0 0 0"
        rpy="0 0 0" />
      <geometry>
        <mesh
          filename="package://xingtian/meshes/imu_link.STL" />
      </geometry>
    </collision>
  </link>
  <joint
    name="imu_joint"
    type="fixed">
    <origin
      xyz="0 0 0.03503"
      rpy="0 0 0" />
    <parent
      link="base_link" />
    <child
      link="imu_link" />
    <axis
      xyz="0 0 0" />
  </joint>
  <link
    name="zht_yao">
    <inertial>
      <origin
        xyz="-0.00155798553474173 0.0585099095625487 0.00176555995432454"
        rpy="0 0 0" />
      <mass
        value="2.36315777456969" />
      <inertia
        ixx="0.00428106185444364"
        ixy="7.54397107095905E-05"
        ixz="0.000207109924987776"
        iyy="0.00741886843255565"
        iyz="-8.54907373814407E-05"
        izz="0.0042291886986985" />
    </inertial>
    <visual>
      <origin
        xyz="0 0 0"
        rpy="0 0 0" />
      <geometry>
        <mesh
          filename="package://xingtian/meshes/zht_yao.STL" />
      </geometry>
      <material
        name="">
        <color
          rgba="0.898039215686275 0.917647058823529 0.929411764705882 1" />
      </material>
    </visual>
    <collision>
      <origin
        xyz="0 0 0"
        rpy="0 0 0" />
      <geometry>
        <mesh
          filename="package://xingtian/meshes/zht_yao.STL" />
      </geometry>
    </collision>
  </link>
  <joint
    name="zht_joint4"
    type="revolute">
    <origin
      xyz="-0.33864 0.0825 -0.00088293"
      rpy="0 0 0" />
    <parent
      link="base_link" />
    <child
      link="zht_yao" />
    <axis
      xyz="0 1 0" />
    <limit
      lower="-3.14"
      upper="3.14"
      effort="2000"
      velocity="3" />
  </joint>
  <link
    name="zht_qubing">
    <inertial>
      <origin
        xyz="-0.00988995989426467 -0.0152193403004889 -0.0345943188524857"
        rpy="0 0 0" />
      <mass
        value="0.343011891033856" />
      <inertia
        ixx="0.000830323173556384"
        ixy="2.44907012177887E-05"
        ixz="-0.000124820230181236"
        iyy="0.000866212607188022"
        iyz="8.56665887322376E-05"
        izz="0.000143538437895095" />
    </inertial>
    <visual>
      <origin
        xyz="0 0 0"
        rpy="0 0 0" />
      <geometry>
        <mesh
          filename="package://xingtian/meshes/zht_qubing.STL" />
      </geometry>
      <material
        name="">
        <color
          rgba="0.898039215686275 0.917647058823529 0.929411764705882 1" />
      </material>
    </visual>
    <collision>
      <origin
        xyz="0 0 0"
        rpy="0 0 0" />
      <geometry>
        <mesh
          filename="package://xingtian/meshes/zht_qubing.STL" />
      </geometry>
    </collision>
  </link>
  <joint
    name="zht_joint3"
    type="revolute">
    <origin
      xyz="0 0.105 0"
      rpy="0 0 0" />
    <parent
      link="zht_yao" />
    <child
      link="zht_qubing" />
    <axis
      xyz="0 1 0" />
    <limit
      lower="-3.14"
      upper="3.14"
      effort="2000"
      velocity="3" />
  </joint>
  <link
    name="zht_dianjizhou">
    <inertial>
      <origin
        xyz="-2.34415518107767E-08 0.0333373294420808 -0.101527239832947"
        rpy="0 0 0" />
      <mass
        value="0.0711999407007276" />
      <inertia
        ixx="0.00020825730700581"
        ixy="9.53214340733863E-12"
        ixz="-4.06153700530492E-11"
        iyy="0.000184277559062658"
        iyz="4.1284477699213E-05"
        izz="3.23488817902417E-05" />
    </inertial>
    <visual>
      <origin
        xyz="0 0 0"
        rpy="0 0 0" />
      <geometry>
        <mesh
          filename="package://xingtian/meshes/zht_dianjizhou.STL" />
      </geometry>
      <material
        name="">
        <color
          rgba="1 1 1 1" />
      </material>
    </visual>
    <collision>
      <origin
        xyz="0 0 0"
        rpy="0 0 0" />
      <geometry>
        <mesh
          filename="package://xingtian/meshes/zht_dianjizhou.STL" />
      </geometry>
    </collision>
  </link>
  <joint
    name="zht_joint2"
    type="revolute">
    <origin
      xyz="0 -0.016 -0.14"
      rpy="0 0 0" />
    <parent
      link="zht_qubing" />
    <child
      link="zht_dianjizhou" />
    <axis
      xyz="0 1 0" />
    <limit
      lower="-3.14"
      upper="3.14"
      effort="2000"
      velocity="3" />
  </joint>

  <link
    name="zht_wheel">
    <inertial>
      <origin
        xyz="2.22044604925031E-16 0.026 -2.22044604925031E-16"
        rpy="0 0 0" />
      <mass
        value="3.44065716846127" />
      <inertia
        ixx="0.00775153539775021"
        ixy="-7.10509709115134E-18"
        ixz="-4.99165251947134E-19"
        iyy="0.0139962639740088"
        iyz="3.57439658150252E-18"
        izz="0.00775153539775021" />
    </inertial>
    <visual>
      <origin
        xyz="0 0 0"
        rpy="0 0 0" />
      <geometry>
        <mesh
          filename="package://xingtian/meshes/zht_wheel.STL" />
      </geometry>
      <material
        name="">
        <color
          rgba="0.898039215686275 0.917647058823529 0.929411764705882 1" />
      </material>
    </visual>
    <collision>
      <origin
        xyz="0 0 0"
        rpy="0 0 0" />
      <geometry>
        <mesh
          filename="package://xingtian/meshes/zht_wheel.STL" />
      </geometry>
    </collision>
  </link>
  <joint
    name="zht_joint1"
    type="continuous">
    <origin
      xyz="0 0.029 -0.14"
      rpy="0 0 0" />
    <parent
      link="zht_dianjizhou" />
    <child
      link="zht_wheel" />
    <axis
      xyz="0 -1 0" />
  </joint>

  <link
    name="yht_yao">
    <inertial>
      <origin
        xyz="-0.00193962758499755 -0.0585099095625487 0.00133505269944491"
        rpy="0 0 0" />
      <mass
        value="2.36315777456969" />
      <inertia
        ixx="0.00418062717932366"
        ixy="-9.39193212219552E-05"
        ixz="0.000194980154391921"
        iyy="0.00741886843255565"
        iyz="6.46450093292299E-05"
        izz="0.00432962337381848" />
    </inertial>
    <visual>
      <origin
        xyz="0 0 0"
        rpy="0 0 0" />
      <geometry>
        <mesh
          filename="package://xingtian/meshes/yht_yao.STL" />
      </geometry>
      <material
        name="">
        <color
          rgba="0.898039215686275 0.917647058823529 0.929411764705882 1" />
      </material>
    </visual>
    <collision>
      <origin
        xyz="0 0 0"
        rpy="0 0 0" />
      <geometry>
        <mesh
          filename="package://xingtian/meshes/yht_yao.STL" />
      </geometry>
    </collision>
  </link>
  <joint
    name="yht_joint4"
    type="revolute">
    <origin
      xyz="-0.33864 -0.0825 -0.00088293"
      rpy="0 0 0" />
    <parent
      link="base_link" />
    <child
      link="yht_yao" />
    <axis
      xyz="0 -1 0" />
    <limit
      lower="-3.14"
      upper="3.14"
      effort="2000"
      velocity="3" />
  </joint>

  <link
    name="yht_qubing">
    <inertial>
      <origin
        xyz="-0.00989009817254993 0.0152193403004836 -0.0345942520471315"
        rpy="0 0 0" />
      <mass
        value="0.343011891033856" />
      <inertia
        ixx="0.000830322140930856"
        ixy="-2.44910555691922E-05"
        ixz="-0.000124823070996035"
        iyy="0.000866212607188024"
        iyz="-8.56664874280724E-05"
        izz="0.000143539470520626" />
    </inertial>
    <visual>
      <origin
        xyz="0 0 0"
        rpy="0 0 0" />
      <geometry>
        <mesh
          filename="package://xingtian/meshes/yht_qubing.STL" />
      </geometry>
      <material
        name="">
        <color
          rgba="0.898039215686275 0.917647058823529 0.929411764705882 1" />
      </material>
    </visual>
    <collision>
      <origin
        xyz="0 0 0"
        rpy="0 0 0" />
      <geometry>
        <mesh
          filename="package://xingtian/meshes/yht_qubing.STL" />
      </geometry>
    </collision>
  </link>

  <joint
    name="yht_joint3"
    type="revolute">
    <origin
      xyz="0 -0.105 0"
      rpy="0 0 0" />
    <parent
      link="yht_yao" />
    <child
      link="yht_qubing" />
    <axis
      xyz="0 1 0" />
    <limit
      lower="-3.14"
      upper="3.14"
      effort="2000"
      velocity="3" />
  </joint>

  <link
    name="yht_dianjizhou">
    <inertial>
      <origin
        xyz="-4.43399224336893E-07 -0.0333373294420808 -0.101527239831984"
        rpy="0 0 0" />
      <mass
        value="0.0711999407007276" />
      <inertia
        ixx="0.000208257307002464"
        ixy="-1.80301418756843E-10"
        ixz="-7.68243669212761E-10"
        iyy="0.000184277559062658"
        iyz="-4.12844776988203E-05"
        izz="3.23488817935874E-05" />
    </inertial>
    <visual>
      <origin
        xyz="0 0 0"
        rpy="0 0 0" />
      <geometry>
        <mesh
          filename="package://xingtian/meshes/yht_dianjizhou.STL" />
      </geometry>
      <material
        name="">
        <color
          rgba="1 1 1 1" />
      </material>
    </visual>
    <collision>
      <origin
        xyz="0 0 0"
        rpy="0 0 0" />
      <geometry>
        <mesh
          filename="package://xingtian/meshes/yht_dianjizhou.STL" />
      </geometry>
    </collision>
  </link>

  <joint
    name="yht_joint2"
    type="revolute">
    <origin
      xyz="0 0.016 -0.14"
      rpy="0 0 0" />
    <parent
      link="yht_qubing" />
    <child
      link="yht_dianjizhou" />
    <axis
      xyz="0 1 0" />
    <limit
      lower="-3.14"
      upper="3.14"
      effort="2000"
      velocity="3" />
  </joint>

  <link
    name="yht_wheel">
    <inertial>
      <origin
        xyz="0 -0.026 0"
        rpy="0 0 0" />
      <mass
        value="3.44065716846127" />
      <inertia
        ixx="0.00775153539775022"
        ixy="6.89009047181592E-18"
        ixz="4.3038795451695E-19"
        iyy="0.0139962639740088"
        iyz="-1.77601595825533E-18"
        izz="0.00775153539775022" />
    </inertial>
    <visual>
      <origin
        xyz="0 0 0"
        rpy="0 0 0" />
      <geometry>
        <mesh
          filename="package://xingtian/meshes/yht_wheel.STL" />
      </geometry>
      <material
        name="">
        <color
          rgba="0.898039215686275 0.917647058823529 0.929411764705882 1" />
      </material>
    </visual>
    <collision>
      <origin
        xyz="0 0 0"
        rpy="0 0 0" />
      <geometry>
        <mesh
          filename="package://xingtian/meshes/yht_wheel.STL" />
      </geometry>
    </collision>
  </link>

  <joint
    name="yht_joint1"
    type="continuous">
    <origin
      xyz="0 -0.029 -0.139999999998665"
      rpy="0 0 0" />
    <parent
      link="yht_dianjizhou" />
    <child
      link="yht_wheel" />
    <axis
      xyz="0 1 0" />
  </joint>

  <link
    name="zqt_yao">
    <inertial>
      <origin
        xyz="0.00121101352565594 0.0585099095625488 -0.00201939771205601"
        rpy="0 0 0" />
      <mass
        value="2.36315777456969" />
      <inertia
        ixx="0.00435340313839109"
        ixy="-5.86388692344531E-05"
        ixz="0.000184143120904003"
        iyy="0.00741886843255565"
        iyz="9.77818957930039E-05"
        izz="0.00415684741475104" />
    </inertial>
    <visual>
      <origin
        xyz="0 0 0"
        rpy="0 0 0" />
      <geometry>
        <mesh
          filename="package://xingtian/meshes/zqt_yao.STL" />
      </geometry>
      <material
        name="">
        <color
          rgba="0.898039215686275 0.917647058823529 0.929411764705882 1" />
      </material>
    </visual>
    <collision>
      <origin
        xyz="0 0 0"
        rpy="0 0 0" />
      <geometry>
        <mesh
          filename="package://xingtian/meshes/zqt_yao.STL" />
      </geometry>
    </collision>
  </link>
  <joint
    name="zqt_joint4"
    type="revolute">
    <origin
      xyz="0.33864 0.0825 -0.00088293"
      rpy="0 0 0" />
    <parent
      link="base_link" />
    <child
      link="zqt_yao" />
    <axis
      xyz="0 1 0" />
    <limit
      lower="-3.14"
      upper="3.14"
      effort="2000"
      velocity="3" />
  </joint>
  <link
    name="zqt_qubing">
    <inertial>
      <origin
        xyz="0.00989010299028142 -0.015219340300489 -0.0345942779430486"
        rpy="0 0 0" />
      <mass
        value="0.343011891033856" />
      <inertia
        ixx="0.000830322140930856"
        ixy="-2.44910555691921E-05"
        ixz="0.000124823070996034"
        iyy="0.000866212607188031"
        iyz="8.56664874280722E-05"
        izz="0.000143539470520632" />
    </inertial>
    <visual>
      <origin
        xyz="0 0 0"
        rpy="0 0 0" />
      <geometry>
        <mesh
          filename="package://xingtian/meshes/zqt_qubing.STL" />
      </geometry>
      <material
        name="">
        <color
          rgba="0.898039215686275 0.917647058823529 0.929411764705882 1" />
      </material>
    </visual>
    <collision>
      <origin
        xyz="0 0 0"
        rpy="0 0 0" />
      <geometry>
        <mesh
          filename="package://xingtian/meshes/zqt_qubing.STL" />
      </geometry>
    </collision>
  </link>
  <joint
    name="zqt_joint3"
    type="revolute">
    <origin
      xyz="0 0.105 0"
      rpy="0 0 0" />
    <parent
      link="zqt_yao" />
    <child
      link="zqt_qubing" />
    <axis
      xyz="0 1 0" />
    <limit
      lower="-3.14"
      upper="3.14"
      effort="2000"
      velocity="3" />
  </joint>
  <link
    name="zqt_dianjizhou">
    <inertial>
      <origin
        xyz="4.43399223913621E-07 0.0333373294420808 -0.101527239831984"
        rpy="0 0 0" />
      <mass
        value="0.0711999407007277" />
      <inertia
        ixx="0.000208257307002464"
        ixy="-1.80301418699056E-10"
        ixz="7.68243669093778E-10"
        iyy="0.000184277559062658"
        iyz="4.12844776988204E-05"
        izz="3.23488817935875E-05" />
    </inertial>
    <visual>
      <origin
        xyz="0 0 0"
        rpy="0 0 0" />
      <geometry>
        <mesh
          filename="package://xingtian/meshes/zqt_dianjizhou.STL" />
      </geometry>
      <material
        name="">
        <color
          rgba="1 1 1 1" />
      </material>
    </visual>
    <collision>
      <origin
        xyz="0 0 0"
        rpy="0 0 0" />
      <geometry>
        <mesh
          filename="package://xingtian/meshes/zqt_dianjizhou.STL" />
      </geometry>
    </collision>
  </link>
  <joint
    name="zqt_joint2"
    type="revolute">
    <origin
      xyz="0 -0.016 -0.14"
      rpy="0 0 0" />
    <parent
      link="zqt_qubing" />
    <child
      link="zqt_dianjizhou" />
    <axis
      xyz="0 1 0" />
    <limit
      lower="-3.14"
      upper="3.14"
      effort="2000"
      velocity="3" />
  </joint>
  <link
    name="zqt_wheel">
    <inertial>
      <origin
        xyz="3.46944695195361E-18 0.026 0"
        rpy="0 0 0" />
      <mass
        value="3.44065716846127" />
      <inertia
        ixx="0.00775153539775022"
        ixy="4.55788597384679E-19"
        ixz="-5.11436726142904E-20"
        iyy="0.0139962639740088"
        iyz="5.56894196526745E-19"
        izz="0.00775153539775022" />
    </inertial>
    <visual>
      <origin
        xyz="0 0 0"
        rpy="0 0 0" />
      <geometry>
        <mesh
          filename="package://xingtian/meshes/zqt_wheel.STL" />
      </geometry>
      <material
        name="">
        <color
          rgba="0.898039215686275 0.917647058823529 0.929411764705882 1" />
      </material>
    </visual>
    <collision>
      <origin
        xyz="0 0 0"
        rpy="0 0 0" />
      <geometry>
        <mesh
          filename="package://xingtian/meshes/zqt_wheel.STL" />
      </geometry>
    </collision>
  </link>
  <joint
    name="zqt_joint1"
    type="continuous">
    <origin
      xyz="0 0.029 -0.14"
      rpy="0 0 0" />
    <parent
      link="zqt_dianjizhou" />
    <child
      link="zqt_wheel" />
    <axis
      xyz="0 -1 0" />
  </joint>
  <link
    name="yqt_yao">
    <inertial>
      <origin
        xyz="-0.00168009360208256 -0.0585099095625488 -0.00164978979479796"
        rpy="0 0 0" />
      <mass
        value="2.36315777456969" />
      <inertia
        ixx="0.00425129166424017"
        ixy="-8.13523440878163E-05"
        ixz="-0.000208692430424964"
        iyy="0.00741886843255565"
        iyz="-7.98849938435662E-05"
        izz="0.00425895888890197" />
    </inertial>
    <visual>
      <origin
        xyz="0 0 0"
        rpy="0 0 0" />
      <geometry>
        <mesh
          filename="package://xingtian/meshes/yqt_yao.STL" />
      </geometry>
      <material
        name="">
        <color
          rgba="0.898039215686275 0.917647058823529 0.929411764705882 1" />
      </material>
    </visual>
    <collision>
      <origin
        xyz="0 0 0"
        rpy="0 0 0" />
      <geometry>
        <mesh
          filename="package://xingtian/meshes/yqt_yao.STL" />
      </geometry>
    </collision>
  </link>
  <joint
    name="yqt_joint4"
    type="revolute">
    <origin
      xyz="0.33864 -0.0825 -0.00088293"
      rpy="0 0 0" />
    <parent
      link="base_link" />
    <child
      link="yqt_yao" />
    <axis
      xyz="0 -1 0" />
    <limit
      lower="-3.14"
      upper="3.14"
      effort="2000"
      velocity="3" />
  </joint>
  <link
    name="yqt_qubing">
    <inertial>
      <origin
        xyz="0.0098899598942902 0.015219340300489 -0.0345943188522134"
        rpy="0 0 0" />
      <mass
        value="0.343011891033856" />
      <inertia
        ixx="0.000830323173556384"
        ixy="2.44907012177889E-05"
        ixz="0.000124820230181238"
        iyy="0.000866212607188013"
        iyz="-8.56665887322375E-05"
        izz="0.000143538437895087" />
    </inertial>
    <visual>
      <origin
        xyz="0 0 0"
        rpy="0 0 0" />
      <geometry>
        <mesh
          filename="package://xingtian/meshes/yqt_qubing.STL" />
      </geometry>
      <material
        name="">
        <color
          rgba="0.898039215686275 0.917647058823529 0.929411764705882 1" />
      </material>
    </visual>
    <collision>
      <origin
        xyz="0 0 0"
        rpy="0 0 0" />
      <geometry>
        <mesh
          filename="package://xingtian/meshes/yqt_qubing.STL" />
      </geometry>
    </collision>
  </link>
  <joint
    name="yqt_joint3"
    type="revolute">
    <origin
      xyz="0 -0.105 0"
      rpy="0 0 0" />
    <parent
      link="yqt_yao" />
    <child
      link="yqt_qubing" />
    <axis
      xyz="0 1 0" />
    <limit
      lower="-3.14"
      upper="3.14"
      effort="2000"
      velocity="3" />
  </joint>
  <link
    name="yqt_dianjizhou">
    <inertial>
      <origin
        xyz="2.34415516858766E-08 -0.0333373294420808 -0.101527239832949"
        rpy="0 0 0" />
      <mass
        value="0.0711999407007277" />
      <inertia
        ixx="0.00020825730700581"
        ixy="9.53214342382804E-12"
        ixz="4.06153701035398E-11"
        iyy="0.000184277559062658"
        iyz="-4.1284477699213E-05"
        izz="3.23488817902417E-05" />
    </inertial>
    <visual>
      <origin
        xyz="0 0 0"
        rpy="0 0 0" />
      <geometry>
        <mesh
          filename="package://xingtian/meshes/yqt_dianjizhou.STL" />
      </geometry>
      <material
        name="">
        <color
          rgba="1 1 1 1" />
      </material>
    </visual>
    <collision>
      <origin
        xyz="0 0 0"
        rpy="0 0 0" />
      <geometry>
        <mesh
          filename="package://xingtian/meshes/yqt_dianjizhou.STL" />
      </geometry>
    </collision>
  </link>
  <joint
    name="yqt_joint2"
    type="revolute">
    <origin
      xyz="0 0.016 -0.14"
      rpy="0 0 0" />
    <parent
      link="yqt_qubing" />
    <child
      link="yqt_dianjizhou" />
    <axis
      xyz="0 1 0" />
    <limit
      lower="-3.14"
      upper="3.14"
      effort="2000"
      velocity="3" />
  </joint>
  <link
    name="yqt_wheel">
    <inertial>
      <origin
        xyz="0 -0.026 0"
        rpy="0 0 0" />
      <mass
        value="3.44065716846127" />
      <inertia
        ixx="0.00775153539775021"
        ixy="-8.07780701845974E-19"
        ixz="-8.66148352262387E-19"
        iyy="0.0139962639740087"
        iyz="9.19191087665601E-19"
        izz="0.00775153539775021" />
    </inertial>
    <visual>
      <origin
        xyz="0 0 0"
        rpy="0 0 0" />
      <geometry>
        <mesh
          filename="package://xingtian/meshes/yqt_wheel.STL" />
      </geometry>
      <material
        name="">
        <color
          rgba="0.898039215686275 0.917647058823529 0.929411764705882 1" />
      </material>
    </visual>
    <collision>
      <origin
        xyz="0 0 0"
        rpy="0 0 0" />
      <geometry>
        <mesh
          filename="package://xingtian/meshes/yqt_wheel.STL" />
      </geometry>
    </collision>
  </link>
  <joint
    name="yqt_joint1"
    type="continuous">
    <origin
      xyz="0 -0.029 -0.139999999999996"
      rpy="0 0 0" />
    <parent
      link="yqt_dianjizhou" />
    <child
      link="yqt_wheel" />
    <axis
      xyz="0 1 0" />
  </joint>
</robot>